2023-09-22 12:09:15,265 INFO    MainThread:4642 [internal.py:wandb_internal():93] W&B internal server running at pid: 4642, started at: 2023-09-22 12:09:15.264834
2023-09-22 12:09:15,271 INFO    WriterThread:4642 [datastore.py:open_for_write():75] open: ./output/sta/StillFast_baseline_0/version_0/wandb/run-20230922_120914-1qzblrtk/run-1qzblrtk.wandb
2023-09-22 12:09:15,278 DEBUG   SenderThread:4642 [sender.py:send():232] send: header
2023-09-22 12:09:15,278 DEBUG   SenderThread:4642 [sender.py:send():232] send: run
2023-09-22 12:09:15,530 ERROR   SenderThread:4642 [internal_api.py:execute():143] 404 response executing GraphQL.
2023-09-22 12:09:15,531 ERROR   SenderThread:4642 [internal_api.py:execute():144] {"errors":[{"message":"entity Lorenzo_Catania_Zgz not found during upsertBucket","path":["upsertBucket"]}],"data":{"upsertBucket":null}}
2023-09-22 12:09:16,272 INFO    HandlerThread:4642 [handler.py:finish():806] shutting down handler
2023-09-22 12:09:16,274 INFO    WriterThread:4642 [datastore.py:close():279] close: ./output/sta/StillFast_baseline_0/version_0/wandb/run-20230922_120914-1qzblrtk/run-1qzblrtk.wandb
2023-09-22 12:09:16,275 ERROR   MainThread:4642 [internal.py:wandb_internal():165] Thread SenderThread:
Traceback (most recent call last):
  File "/home/lmur/miniconda3/envs/stillfast/lib/python3.7/site-packages/wandb/sdk/lib/retry.py", line 102, in __call__
    result = self._call_fn(*args, **kwargs)
  File "/home/lmur/miniconda3/envs/stillfast/lib/python3.7/site-packages/wandb/sdk/internal/internal_api.py", line 140, in execute
    return self.client.execute(*args, **kwargs)
  File "/home/lmur/miniconda3/envs/stillfast/lib/python3.7/site-packages/wandb/vendor/gql-0.2.0/wandb_gql/client.py", line 52, in execute
    result = self._get_result(document, *args, **kwargs)
  File "/home/lmur/miniconda3/envs/stillfast/lib/python3.7/site-packages/wandb/vendor/gql-0.2.0/wandb_gql/client.py", line 60, in _get_result
    return self.transport.execute(document, *args, **kwargs)
  File "/home/lmur/miniconda3/envs/stillfast/lib/python3.7/site-packages/wandb/vendor/gql-0.2.0/wandb_gql/transport/requests.py", line 39, in execute
    request.raise_for_status()
  File "/home/lmur/miniconda3/envs/stillfast/lib/python3.7/site-packages/requests/models.py", line 1021, in raise_for_status
    raise HTTPError(http_error_msg, response=self)
requests.exceptions.HTTPError: 404 Client Error: Not Found for url: https://api.wandb.ai/graphql

During handling of the above exception, another exception occurred:

Traceback (most recent call last):
  File "/home/lmur/miniconda3/envs/stillfast/lib/python3.7/site-packages/wandb/apis/normalize.py", line 22, in wrapper
    return func(*args, **kwargs)
  File "/home/lmur/miniconda3/envs/stillfast/lib/python3.7/site-packages/wandb/sdk/internal/internal_api.py", line 1319, in upsert_run
    response = self.gql(mutation, variable_values=variable_values, **kwargs)
  File "/home/lmur/miniconda3/envs/stillfast/lib/python3.7/site-packages/wandb/sdk/lib/retry.py", line 118, in __call__
    if not check_retry_fn(e):
  File "/home/lmur/miniconda3/envs/stillfast/lib/python3.7/site-packages/wandb/util.py", line 882, in no_retry_auth
    raise CommError("Permission denied, ask the project owner to grant you access")
wandb.errors.CommError: Permission denied, ask the project owner to grant you access

During handling of the above exception, another exception occurred:

Traceback (most recent call last):
  File "/home/lmur/miniconda3/envs/stillfast/lib/python3.7/site-packages/wandb/sdk/internal/internal_util.py", line 51, in run
    self._run()
  File "/home/lmur/miniconda3/envs/stillfast/lib/python3.7/site-packages/wandb/sdk/internal/internal_util.py", line 102, in _run
    self._process(record)
  File "/home/lmur/miniconda3/envs/stillfast/lib/python3.7/site-packages/wandb/sdk/internal/internal.py", line 310, in _process
    self._sm.send(record)
  File "/home/lmur/miniconda3/envs/stillfast/lib/python3.7/site-packages/wandb/sdk/internal/sender.py", line 234, in send
    send_handler(record)
  File "/home/lmur/miniconda3/envs/stillfast/lib/python3.7/site-packages/wandb/sdk/internal/sender.py", line 692, in send_run
    self._init_run(run, config_value_dict)
  File "/home/lmur/miniconda3/envs/stillfast/lib/python3.7/site-packages/wandb/sdk/internal/sender.py", line 730, in _init_run
    commit=run.git.last_commit or None,
  File "/home/lmur/miniconda3/envs/stillfast/lib/python3.7/site-packages/wandb/apis/normalize.py", line 58, in wrapper
    raise CommError(message, err).with_traceback(sys.exc_info()[2])
  File "/home/lmur/miniconda3/envs/stillfast/lib/python3.7/site-packages/wandb/apis/normalize.py", line 22, in wrapper
    return func(*args, **kwargs)
  File "/home/lmur/miniconda3/envs/stillfast/lib/python3.7/site-packages/wandb/sdk/internal/internal_api.py", line 1319, in upsert_run
    response = self.gql(mutation, variable_values=variable_values, **kwargs)
  File "/home/lmur/miniconda3/envs/stillfast/lib/python3.7/site-packages/wandb/sdk/lib/retry.py", line 118, in __call__
    if not check_retry_fn(e):
  File "/home/lmur/miniconda3/envs/stillfast/lib/python3.7/site-packages/wandb/util.py", line 882, in no_retry_auth
    raise CommError("Permission denied, ask the project owner to grant you access")
wandb.errors.CommError: Permission denied, ask the project owner to grant you access
2023-09-22 12:09:18,316 INFO    MainThread:4642 [internal.py:handle_exit():80] Internal process exited
